<?xml version="1.0"?>
<robot name="oven">

  <link name="oven_body">
    <visual>
      <geometry>
        <box size="0.2 0.2 0.2"/>
      </geometry>
      <material name="gray">
        <color rgba="0.5 0.5 0.5 1"/>
      </material>
      <origin xyz="0 0 0.1"/>
    </visual>
    <collision>
      <geometry>
        <box size="0.2 0.2 0.2"/>
      </geometry>
      <origin xyz="0 0 0.1"/>
    </collision>
    <inertial>
      <mass value="5"/>
      <inertia ixx="0.1" ixy="0" ixz="0" iyy="0.1" iyz="0" izz="0.1"/>
    </inertial>
  </link>

  <joint name="oven_hinge" type="revolute">
    <axis xyz="0 1 0"/>
    <limit effort="100.0" lower="0.0" upper="1.57" velocity="10"/>
    <parent link="oven_body"/>
    <child link="oven_door"/>
    <origin xyz="0.1 0 0.02"/>
  </joint>

  <link name="oven_door">
    <visual>
      <geometry>
        <box size="0.01 0.2 0.18"/>
      </geometry>
      <material name="white">
        <color rgba="1 1 1 1"/>
      </material>
      <origin xyz="0 0 0.09"/>
    </visual>
    <collision>
      <geometry>
        <box size="0.01 0.2 0.18"/>
      </geometry>
      <origin xyz="0 0 0.09"/>
    </collision>
    <inertial>
      <mass value="0.5"/>
      <inertia ixx="0.01" ixy="0" ixz="0" iyy="0.01" iyz="0" izz="0.01"/>
    </inertial>
  </link>

  <joint name="handle_joint" type="fixed">
    <parent link="oven_door"/>
    <child link="oven_handle"/>
    <origin xyz="0.015 0 0.16"/>
  </joint>

  <link name="oven_handle">
    <visual>
      <geometry>
        <box size="0.02 0.15 0.015"/>
      </geometry>
      <material name="red">
        <color rgba="1 0 0 1"/>
      </material>
    </visual>
    <collision>
      <geometry>
        <box size="0.02 0.15 0.015"/>
      </geometry>
    </collision>
    <inertial>
      <mass value="0.1"/>
      <inertia ixx="0.001" ixy="0" ixz="0" iyy="0.001" iyz="0" izz="0.001"/>
    </inertial>
  </link>

</robot>